<?xml version='1.0'?>
<robot name="rover">

  <!-- Base Link -->
  <link name="base_link">
    <visual>
      <origin xyz="0 0 0.085" rpy="0 0 0" />
      <geometry>
          <box size="0.4 0.25 0.035"/>
      </geometry>
    </visual>
    <!-- Base collision, mass and inertia -->
    <collision>
      <origin xyz="0 0 0.1" rpy="0 0 0" />
      <geometry>
          <box size="0.4 0.25 0.035"/>
      </geometry>
    </collision>
    <inertial>
      <mass value="0.85"/>
      <inertia ixx="0.0" ixy="0.0" ixz="0.0" iyy="0.021" iyz="0.0" izz="0.01"/>
    </inertial>
  </link>

  <gazebo reference="base_link">
    <material>Gazebo/Blue</material>
    <pose>0 0 3 0 0 0</pose>
  </gazebo>

  <!-- Right Wheel -->
  <link name="right_wheel">
    <visual>
      <origin xyz="0 0 0" rpy="1.570795 0 0" />
      <geometry>
          <cylinder length="0.057" radius="0.0625" />
      </geometry>
    </visual>
    <!-- Right Wheel collision, mass and inertia -->
    <collision>
      <origin xyz="0 0 0" rpy="1.570795 0 0" />
      <geometry>
          <cylinder length="0.057" radius="0.0625" />
      </geometry>
    </collision>
    <inertial>
      <mass value="0.158"/>
      <inertia ixx="0.0002" ixy="0.0" ixz="0.0" iyy="0.0002" iyz="0.0" izz="0.0003"/>
    </inertial>

  </link>

  <gazebo reference="right_wheel">
    <material>Gazebo/Black</material>
  </gazebo>

  <!-- Right Wheel joint -->
  <joint name="right_wheel_joint" type="continuous">
    <parent link="base_link"/>
    <child link="right_wheel"/>
    <origin xyz="-0.152 -0.161 0.0825" rpy="0 0 0" /> 
    <axis xyz="0 1 0" />
  </joint>

<transmission name="right_wheel_joint_trans" type="SimpleTransmission">
    <type>transmission_interface/SimpleTransmission</type>
    <actuator name="right_wheel_joint_motor">
      <mechanicalReduction>1</mechanicalReduction>
    </actuator>
    <joint name="right_wheel_joint">
      <hardwareInterface>hardware_interface/VelocityJointInterface</hardwareInterface>
    </joint>
  </transmission>

  <!-- Left Wheel -->
  <link name="left_wheel">
    <visual>
      <origin xyz="0 0 0" rpy="1.570795 0 0" />
      <geometry>
          <cylinder length="0.057" radius="0.0625" />
      </geometry>
    </visual>
    <!-- Left Wheel collision, mass and inertia -->
    <collision>
      <origin xyz="0 0 0" rpy="1.570795 0 0" />
      <geometry>
          <cylinder length="0.057" radius="0.0625" />
      </geometry>
    </collision>
    <inertial>
      <mass value="0.158"/>
      <inertia ixx="0.01" ixy="0.0" ixz="0.0" iyy="0.005" iyz="0.0" izz="0.005"/>
    </inertial>
  </link>

  
  <gazebo reference="left_wheel">
    <material>Gazebo/Black</material>
  </gazebo>

  <!-- Left Wheel joint -->
  <joint name="left_wheel_joint" type="continuous">
    <parent link="base_link"/>
    <child link="left_wheel"/>
    <origin xyz="-0.152 0.161 0.0825" rpy="0 0 0" /> 
    <axis xyz="0 1 0"/>
  </joint>

<transmission name="left_wheel_joint_trans" type="SimpleTransmission">
    <type>transmission_interface/SimpleTransmission</type>
    <actuator name="left_wheel_joint_motor">
      <mechanicalReduction>1</mechanicalReduction>
    </actuator>
    <joint name="left_wheel_joint">
      <hardwareInterface>hardware_interface/VelocityJointInterface</hardwareInterface>
    </joint>
  </transmission>


  <!-- Right Wheel -->
  <link name="front_right_wheel">
    <visual>
      <origin xyz="0 0 0" rpy="1.570795 0 0" />
      <geometry>
          <cylinder length="0.057" radius="0.0625" />
      </geometry>
    </visual>
    <!-- Right Wheel collision, mass and inertia -->
    <collision>
      <origin xyz="0 0 0" rpy="1.570795 0 0" />
      <geometry>
          <cylinder length="0.057" radius="0.0625" />
      </geometry>
    </collision>
    <inertial>
      <mass value="0.158"/>
      <inertia ixx="0.01" ixy="0.0" ixz="0.0" iyy="0.005" iyz="0.0" izz="0.005"/>
    </inertial>

  </link>

  <gazebo reference="front_right_wheel">
    <material>Gazebo/Black</material>
  </gazebo>

  <!-- Right Wheel joint -->
  <joint name="front_right_wheel_joint" type="continuous">
    <parent link="base_link"/>
    <child link="front_right_wheel"/>
    <origin xyz="0.152 -0.161 0.0825" rpy="0 0 0" /> 
    <axis xyz="0 1 0" />
  </joint>

<transmission name="front_right_wheel_joint_trans" type="SimpleTransmission">
    <type>transmission_interface/SimpleTransmission</type>
    <actuator name="front_right_wheel_joint_motor">
      <mechanicalReduction>1</mechanicalReduction>
    </actuator>
    <joint name="front_right_wheel_joint">
      <hardwareInterface>hardware_interface/VelocityJointInterface</hardwareInterface>
    </joint>
  </transmission>


  <!-- Left Wheel -->
  <link name="front_left_wheel">
    <visual>
      <origin xyz="0 0 0" rpy="1.570795 0 0" />
      <geometry>
          <cylinder length="0.057" radius="0.0625" />
      </geometry>
    </visual>
    <!-- Left Wheel collision, mass and inertia -->
    <collision>
      <origin xyz="0 0 0" rpy="1.570795 0 0" />
      <geometry>
          <cylinder length="0.057" radius="0.0625" />
      </geometry>
    </collision>
    <inertial>
      <mass value="0.158"/>
      <inertia ixx="0.01" ixy="0.0" ixz="0.0" iyy="0.005" iyz="0.0" izz="0.005"/>
    </inertial>
  </link>

  
  <gazebo reference="front_left_wheel">
    <material>Gazebo/Black</material>
  </gazebo>

  <!-- Left Wheel joint -->
  <joint name="front_left_wheel_joint" type="continuous">
    <parent link="base_link"/>
    <child link="front_left_wheel"/>
    <origin xyz="0.152 0.161 0.0825" rpy="0 0 0" /> 
    <axis xyz="0 1 0"/>
  </joint>
<transmission name="front_left_wheel_joint_trans" type="SimpleTransmission">
    <type>transmission_interface/SimpleTransmission</type>
    <actuator name="front_left_wheel_joint_motor">
      <mechanicalReduction>1</mechanicalReduction>
    </actuator>
    <joint name="front_left_wheel_joint">
      <hardwareInterface>hardware_interface/VelocityJointInterface</hardwareInterface>
    </joint>
  </transmission>
<!--origin change to xyz=0 0 0.12-->
  <joint name="hjoint" type="fixed">
    <axis xyz="0 0 1" />
    <origin xyz="0.0 -0.0625 0.12" rpy="0 0 0"/>
    <parent link="base_link"/>
    <child link="hlink"/>
  </joint>

  <link name="hlink">
    <visual>
      <origin xyz="0 0 0" rpy="0 0 0"/>
      <geometry>
        <box size="0.12 0.1 0.06"/>
      </geometry>
    </visual>

    <collision>
      <origin xyz="0 0 0" rpy="0 0 0"/>
      <geometry>
        <box size="0.12 0.1 0.06"/>
      </geometry>
    </collision>

    <inertial>
      <mass value="0.128" />
      <origin xyz="0 0 0" rpy="0 0 0"/>
      <inertia ixx="0.0004" ixy="0" ixz="0" iyy="0.0003" iyz="0" izz="0.0004" />
    </inertial>
  </link>


   <!-- *****************************RP Laser***************************** -->
<!--origin change to xyz=0 0 0.12-->
  <joint name="RP_joint" type="fixed">
    <axis xyz="0 0 1" />
    <origin xyz="0.0 -0.0625 0.178" rpy="0 0 0"/>
    <parent link="base_link"/>
    <child link="RP_link"/>
  </joint>

  <link name="RP_link">
    <visual>
      <origin xyz="0 0 0" rpy="0 0 0"/>
      <geometry>
        <box size="0.097 0.07 0.058"/>
      </geometry>
    </visual>

    <collision>
      <origin xyz="0 0 0" rpy="0 0 0"/>
      <geometry>
        <box size="0.097 0.07 0.058"/>
      </geometry>
    </collision>

    <inertial>
      <mass value="0.75" />
      <origin xyz="0 0 0" rpy="0 0 0"/>
      <inertia ixx="0.1" ixy="-0.01" ixz="0" iyy="0" iyz="0.02" izz="0.1" />
    </inertial>
  </link>



  <!-- hokuyo -->
  <gazebo reference="RP_link">
    <sensor type="ray" name="head_RP_sensor">
      <pose>0.0 0 0.0 0 0 0</pose>
      <ray>
        <scan>
          <horizontal>
            <samples>720</samples>
            <resolution>1</resolution>
            <min_angle>-3.14159265</min_angle>
            <max_angle>3.14159265</max_angle>
          </horizontal>
        </scan>
        <range>
          <min>0.2</min>
          <max>6</max>
          <resolution>0.01</resolution>
        </range>
        <noise>
          <type>gaussian</type>
          <mean>0.0</mean>
          <stddev>0.01</stddev>
        </noise>
      </ray>
      <plugin name="gazebo_ros_head_rplidar_controller" filename="libgazebo_ros_laser.so">
        <always_on>1</always_on>
        <topicName>/scan</topicName>
        <frameName>RP_link</frameName>
      </plugin>
      <always_on>1</always_on>
      <update_rate>80</update_rate>
      <visualize>false</visualize>
    </sensor>
  </gazebo>

 <gazebo reference="RP_link">
    <material>Gazebo/Orange</material>
  </gazebo>



  <gazebo reference="front_right_wheel">
<kp>1000000.0</kp> <!-- kp and kd for rubber -->
<kd>100.0</kd>
<mu1>1.0</mu1>
<mu2>1.0</mu2>
<maxVel>1.0</maxVel>
<minDepth>0.00</minDepth>
  </gazebo>
  <gazebo reference="front_left_wheel">
<kp>1000000.0</kp> <!-- kp and kd for rubber -->
<kd>100.0</kd>
<mu1>1.0</mu1>
<mu2>1.0</mu2>
<maxVel>1.0</maxVel>
<minDepth>0.00</minDepth>
  </gazebo>
  <gazebo reference="right_wheel">
<kp>1000000.0</kp> <!-- kp and kd for rubber -->
<kd>100.0</kd>
<mu1>1.0</mu1>
<mu2>1.0</mu2>
<maxVel>1.0</maxVel>
<minDepth>0.00</minDepth>
  </gazebo>
  <gazebo reference="left_wheel">
<kp>1000000.0</kp> <!-- kp and kd for rubber -->
<kd>100.0</kd>
<mu1>1.0</mu1>
<mu2>1.0</mu2>
<maxVel>1.0</maxVel>
<minDepth>0.00</minDepth>
  </gazebo>

  <gazebo>
    <plugin filename="libgazebo_ros_control.so" name="gazebo_ros_control">
      <robotNamespace>/</robotNamespace>
      <legacyModeNS>true</legacyModeNS>
    </plugin>
  </gazebo>
  <gazebo>
<plugin name='skid_steer_drive' filename='libgazebo_ros_skid_steer_drive.so'>
        <updateRate>500</updateRate>

        <leftFrontJoint>front_left_wheel_joint</leftFrontJoint>
        <rightFrontJoint>front_right_wheel_joint</rightFrontJoint>
        <leftRearJoint>left_wheel_joint</leftRearJoint>
        <rightRearJoint>right_wheel_joint</rightRearJoint>
        <wheelSeparation>0.304</wheelSeparation>
        <wheelDiameter>0.125</wheelDiameter>
        <torque>200</torque>

        <commandTopic>cmd_vel</commandTopic>
        <odometryTopic>odom</odometryTopic>
        <odometryFrame>odom</odometryFrame>
        <robotBaseFrame>base_link</robotBaseFrame>
        <broadcastTF>true</broadcastTF>
      </plugin>
  </gazebo>

</robot>

